<mujoco model="H1-2 + Inspire Bimanual (position actuators)">
  <!--
    H1-2 humanoid with BOTH Inspire hands — bimanual position-actuator variant.
    Used by grasp_viz h12 bimanual for dual-arm grasp planning.

    Right hand attachment (right_wrist_yaw_link → hand base):
      pos="0.054 0 0"  quat="0.5 0.5 0.5 0.5"
    Left hand attachment (left_wrist_yaw_link → hand base):
      pos="0.054 0 0"  quat="0.5 -0.5 0.5 -0.5"
      R: [x,y,z] in hand → [z,-x,-y]+[0.054,0,0] in wrist
      (verified: thumb_base [0.017,-0.020,0.069] → [0.123,-0.017,0.020] matches h1_2_pos_hands.xml)
  -->
  <compiler angle="radian" meshdir="assets" autolimits="true"/>

  <visual>
    <headlight ambient=".4 .4 .4" diffuse=".8 .8 .8" specular="0.1 0.1 0.1"/>
    <map znear=".01"/>
    <quality shadowsize="2048"/>
    <global elevation="-15"/>
  </visual>

  <default>
    <default class="h1_2">
      <joint damping="1" armature="0.1"/>
      <default class="hip">
        <position forcerange="-200 200" kp="200" kv="5"/>
      </default>
      <default class="knee">
        <position forcerange="-300 300" kp="300" kv="6"/>
      </default>
      <default class="ankle1">
        <position forcerange="-60 60" kp="40" kv="2"/>
      </default>
      <default class="ankle2">
        <position forcerange="-40 40" kp="40" kv="2"/>
      </default>
      <default class="torso">
        <position forcerange="-200 200" kp="300" kv="6"/>
      </default>
      <default class="shoulder1">
        <position forcerange="-40 40" kp="100" kv="2"/>
      </default>
      <default class="shoulder2">
        <position forcerange="-18 18" kp="100" kv="2"/>
      </default>
      <default class="elbow">
        <position forcerange="-18 18" kp="100" kv="2"/>
      </default>
      <default class="wrist">
        <position forcerange="-19 19" kp="100" kv="2"/>
      </default>
    </default>

    <!-- Inspire hand defaults -->
    <default class="inspire">
      <position kp="100" dampratio="1.0"/>
      <joint damping="0.1" armature="0.01" frictionloss="0.001"/>
      <material specular="0.5" shininess="0.25"/>
      <default class="visual">
        <geom type="mesh" contype="0" conaffinity="0" group="2" rgba="0.1 0.1 0.1 1"/>
      </default>
      <default class="collision">
        <geom type="mesh" group="3" condim="4" friction="1 0.005 0.001" solref="0.002 1" solimp="0.9 0.95 0.001"/>
        <default class="pad_box1">
          <geom mass="0" type="box" pos="0.003 -0.02227 0.0113" size="0.008 0.0015 0.01" friction="0.6" solimp="0.95 0.99 0.001" solref="0.004 1" priority="1" rgba="0.55 0.55 0.55 1"/>
        </default>
        <default class="pad_box2">
          <geom mass="0" type="box" pos="0.003 -0.02227 0.0313" size="0.008 0.0015 0.01" friction="0.6" solimp="0.95 0.99 0.001" solref="0.004 1" priority="1" rgba="0.45 0.45 0.45 1"/>
        </default>
        <default class="pad_box3">
          <geom mass="0" type="box" pos="0.003 -0.02227 0.0513" size="0.008 0.0015 0.01" friction="0.6" solimp="0.95 0.99 0.001" solref="0.004 1" priority="1" rgba="0.55 0.55 0.55 1"/>
        </default>
        <default class="pad_box4">
          <geom mass="0" type="box" pos="0.003 -0.02227 0.0713" size="0.008 0.0015 0.01" friction="0.6" solimp="0.95 0.99 0.001" solref="0.004 1" priority="1" rgba="0.45 0.45 0.45 1"/>
        </default>
        <default class="pad_box5">
          <geom mass="0" type="box" pos="0.003 0.02227 0.0113" size="0.008 0.0015 0.01" friction="0.6" solimp="0.95 0.99 0.001" solref="0.004 1" priority="1" rgba="0.55 0.55 0.55 1"/>
        </default>
        <default class="pad_box6">
          <geom mass="0" type="box" pos="0.003 0.02227 0.0313" size="0.008 0.0015 0.01" friction="0.6" solimp="0.95 0.99 0.001" solref="0.004 1" priority="1" rgba="0.45 0.45 0.45 1"/>
        </default>
        <default class="pad_box7">
          <geom mass="0" type="box" pos="0.003 0.02227 0.0513" size="0.008 0.0015 0.01" friction="0.6" solimp="0.95 0.99 0.001" solref="0.004 1" priority="1" rgba="0.55 0.55 0.55 1"/>
        </default>
        <default class="pad_box8">
          <geom mass="0" type="box" pos="0.003 0.02227 0.0713" size="0.008 0.0015 0.01" friction="0.6" solimp="0.95 0.99 0.001" solref="0.004 1" priority="1" rgba="0.45 0.45 0.45 1"/>
        </default>
      </default>
      <site size="0.0035" type="sphere" rgba="1 0 0 1" group="3"/>
    </default>
  </default>

  <asset>
    <!-- Sky and ground -->
    <texture name="skybox" type="skybox" builtin="gradient" rgb1="0.3 0.5 0.7" rgb2="0 0 0" width="512" height="3072"/>
    <texture name="texplane" type="2d" builtin="checker" rgb1=".2 .3 .4" rgb2=".1 .2 .3" width="512" height="512" mark="edge" markrgb=".8 .8 .8"/>
    <material name="groundplane" texture="texplane" texuniform="true" texrepeat="5 5" reflectance="0.2"/>

    <!-- H1-2 meshes -->
    <mesh name="pelvis" file="h1_2_meshes/pelvis.STL"/>
    <mesh name="left_hip_yaw_link" file="h1_2_meshes/left_hip_yaw_link.STL"/>
    <mesh name="left_hip_pitch_link" file="h1_2_meshes/left_hip_pitch_link.STL"/>
    <mesh name="left_hip_roll_link" file="h1_2_meshes/left_hip_roll_link.STL"/>
    <mesh name="left_knee_link" file="h1_2_meshes/left_knee_link.STL"/>
    <mesh name="left_ankle_pitch_link" file="h1_2_meshes/left_ankle_pitch_link.STL"/>
    <mesh name="left_ankle_roll_link" file="h1_2_meshes/left_ankle_roll_link.STL"/>
    <mesh name="right_hip_yaw_link" file="h1_2_meshes/right_hip_yaw_link.STL"/>
    <mesh name="right_hip_pitch_link" file="h1_2_meshes/right_hip_pitch_link.STL"/>
    <mesh name="right_hip_roll_link" file="h1_2_meshes/right_hip_roll_link.STL"/>
    <mesh name="right_knee_link" file="h1_2_meshes/right_knee_link.STL"/>
    <mesh name="right_ankle_pitch_link" file="h1_2_meshes/right_ankle_pitch_link.STL"/>
    <mesh name="right_ankle_roll_link" file="h1_2_meshes/right_ankle_roll_link.STL"/>
    <mesh name="torso_link" file="h1_2_meshes/torso_link.STL"/>
    <mesh name="left_shoulder_pitch_link" file="h1_2_meshes/left_shoulder_pitch_link.STL"/>
    <mesh name="left_shoulder_roll_link" file="h1_2_meshes/left_shoulder_roll_link.STL"/>
    <mesh name="left_shoulder_yaw_link" file="h1_2_meshes/left_shoulder_yaw_link.STL"/>
    <mesh name="left_elbow_link" file="h1_2_meshes/left_elbow_link.STL"/>
    <mesh name="left_wrist_roll_link" file="h1_2_meshes/left_wrist_roll_link.STL"/>
    <mesh name="left_wrist_pitch_link" file="h1_2_meshes/left_wrist_pitch_link.STL"/>
    <mesh name="wrist_yaw_link" file="h1_2_meshes/wrist_yaw_link.STL"/>
    <mesh name="right_shoulder_pitch_link" file="h1_2_meshes/right_shoulder_pitch_link.STL"/>
    <mesh name="right_shoulder_roll_link" file="h1_2_meshes/right_shoulder_roll_link.STL"/>
    <mesh name="right_shoulder_yaw_link" file="h1_2_meshes/right_shoulder_yaw_link.STL"/>
    <mesh name="right_elbow_link" file="h1_2_meshes/right_elbow_link.STL"/>
    <mesh name="right_wrist_roll_link" file="h1_2_meshes/right_wrist_roll_link.STL"/>
    <mesh name="right_wrist_pitch_link" file="h1_2_meshes/right_wrist_pitch_link.STL"/>
    <mesh name="logo_link" file="h1_2_meshes/logo_link.STL"/>

    <!-- Magpie gripper meshes -->
    <mesh name="h12_mount" file="magpie_h12.stl" scale="0.001 0.001 0.001"/>
    <mesh name="magpie_mount" file="mount.stl" scale="0.001 0.001 0.001"/>
    <mesh name="magpie_base_bot" file="base_bot.stl" scale="0.001 0.001 0.001"/>
    <mesh name="magpie_base_top" file="base_top.stl" scale="0.001 0.001 0.001"/>
    <mesh name="magpie_left_crank" file="left_crank.stl" scale="0.001 0.001 0.001"/>
    <mesh name="magpie_right_crank" file="right_crank.stl" scale="0.001 0.001 0.001"/>
    <mesh name="magpie_left_finger" file="left_finger_combined.stl" scale="0.001 0.001 0.001"/>
    <mesh name="magpie_right_finger" file="right_finger_combined.stl" scale="0.001 0.001 0.001"/>
    <mesh name="magpie_left_rocker" file="left_rocker.stl" scale="0.001 0.001 0.001"/>
    <mesh name="magpie_right_rocker" file="right_rocker.stl" scale="0.001 0.001 0.001"/>

  </asset>

  <worldbody>
    <!-- Floor and lighting -->
    <geom name="floor" pos="0 0 0" size="0 0 0.05" type="plane" material="groundplane"/>
    <light name="light0" mode="fixed" pos="-2 -2 6" dir=".5 .5 -1" cutoff="60" diffuse="0.5 0.5 0.5" specular="0.3 0.3 0.3"/>
    <light name="light1" mode="fixed" pos=" 2 -2 6" dir="-.5 .5 -1" cutoff="60" diffuse="0.5 0.5 0.5" specular="0.3 0.3 0.3"/>
    <light name="light2" mode="fixed" pos="0  3 6" dir="0 -.5 -1" cutoff="60" diffuse="0.3 0.3 0.3" specular="0.1 0.1 0.1"/>

    <body name="pelvis" pos="0 0 1.03" childclass="h1_2">
      <inertial pos="-0.0004 3.7e-05 -0.046864" quat="0.497097 0.496809 -0.503132 0.502925" mass="5.983" diaginertia="0.0531565 0.0491678 0.00902583"/>
      <joint name="floating_base_joint" type="free" limited="false" actuatorfrclimited="false"/>
      <geom type="mesh" contype="0" conaffinity="0" group="1" density="0" rgba="0.1 0.1 0.1 1" mesh="pelvis"/>
      <geom size="0.05" rgba="0.1 0.1 0.1 1"/>
      <body name="left_hip_yaw_link" pos="0 0.0875 -0.1632">
        <inertial pos="0 -0.026197 0.006647" quat="0.704899 -0.0553755 0.0548434 0.705013" mass="2.829" diaginertia="0.00574303 0.00455361 0.00349461"/>
        <joint name="left_hip_yaw_joint" pos="0 0 0" axis="0 0 1" range="-0.43 0.43" actuatorfrcrange="-200 200"/>
        <geom type="mesh" contype="0" conaffinity="0" group="1" density="0" rgba="0.1 0.1 0.1 1" mesh="left_hip_yaw_link"/>
        <body name="left_hip_pitch_link" pos="0 0.0755 0">
          <inertial pos="-0.00781 -0.004724 -6.3e-05" quat="0.701575 0.711394 0.0330266 0.0249149" mass="2.92" diaginertia="0.00560661 0.00445055 0.00385068"/>
          <joint name="left_hip_pitch_joint" pos="0 0 0" axis="0 1 0" range="-3.14 2.5" actuatorfrcrange="-200 200"/>
          <geom type="mesh" contype="0" conaffinity="0" group="1" density="0" rgba="0.1 0.1 0.1 1" mesh="left_hip_pitch_link"/>
          <geom type="mesh" rgba="0.1 0.1 0.1 1" mesh="left_hip_pitch_link"/>
          <body name="left_hip_roll_link">
            <inertial pos="0.004171 -0.008576 -0.194509" quat="0.634842 0.0146079 0.0074063 0.772469" mass="4.962" diaginertia="0.0480229 0.0462788 0.00887409"/>
            <joint name="left_hip_roll_joint" pos="0 0 0" axis="1 0 0" range="-0.43 3.14" actuatorfrcrange="-200 200"/>
            <geom type="mesh" contype="0" conaffinity="0" group="1" density="0" rgba="0.1 0.1 0.1 1" mesh="left_hip_roll_link"/>
            <body name="left_knee_link" pos="0 0 -0.4">
              <inertial pos="0.000179 0.000121 -0.168936" quat="0.416585 0.0104983 0.00514003 0.909021" mass="3.839" diaginertia="0.0391044 0.038959 0.00501125"/>
              <joint name="left_knee_joint" pos="0 0 0" axis="0 1 0" range="-0.12 2.19" actuatorfrcrange="-300 300"/>
              <geom type="mesh" contype="0" conaffinity="0" group="1" density="0" rgba="0.1 0.1 0.1 1" mesh="left_knee_link"/>
              <body name="left_ankle_pitch_link" pos="0 0 -0.4">
                <inertial pos="-0.000294 0 -0.010794" quat="0.999984 0 -0.00574445 0" mass="0.102" diaginertia="2.39454e-05 2.1837e-05 1.34126e-05"/>
                <joint name="left_ankle_pitch_joint" pos="0 0 0" axis="0 1 0" range="-0.897334 0.523598" actuatorfrcrange="-60 60"/>
                <geom type="mesh" contype="0" conaffinity="0" group="1" density="0" rgba="0.1 0.1 0.1 1" mesh="left_ankle_pitch_link"/>
                <body name="left_ankle_roll_link" pos="0 0 -0.02">
                  <inertial pos="0.029589 0 -0.015973" quat="0 0.725858 0 0.687845" mass="0.747" diaginertia="0.00359178 0.00343534 0.000640307"/>
                  <joint name="left_ankle_roll_joint" pos="0 0 0" axis="1 0 0" range="-0.261799 0.261799" actuatorfrcrange="-40 40"/>
                  <geom type="mesh" contype="0" conaffinity="0" group="1" density="0" rgba="0.1 0.1 0.1 1" mesh="left_ankle_roll_link"/>
                  <geom type="mesh" rgba="0.1 0.1 0.1 1" mesh="left_ankle_roll_link"/>
                </body>
              </body>
            </body>
          </body>
        </body>
      </body>
      <body name="right_hip_yaw_link" pos="0 -0.0875 -0.1632">
        <inertial pos="0 0.026197 0.006647" quat="0.705013 0.0548434 -0.0553755 0.704899" mass="2.829" diaginertia="0.00574303 0.00455361 0.00349461"/>
        <joint name="right_hip_yaw_joint" pos="0 0 0" axis="0 0 1" range="-0.43 0.43" actuatorfrcrange="-200 200"/>
        <geom type="mesh" contype="0" conaffinity="0" group="1" density="0" rgba="0.1 0.1 0.1 1" mesh="right_hip_yaw_link"/>
        <body name="right_hip_pitch_link" pos="0 -0.0755 0">
          <inertial pos="-0.00781 0.004724 -6.3e-05" quat="0.711394 0.701575 -0.0249149 -0.0330266" mass="2.92" diaginertia="0.00560661 0.00445055 0.00385068"/>
          <joint name="right_hip_pitch_joint" pos="0 0 0" axis="0 1 0" range="-3.14 2.5" actuatorfrcrange="-200 200"/>
          <geom type="mesh" contype="0" conaffinity="0" group="1" density="0" rgba="0.1 0.1 0.1 1" mesh="right_hip_pitch_link"/>
          <body name="right_hip_roll_link">
            <inertial pos="0.004171 0.008576 -0.194509" quat="0.772469 0.0074063 0.0146079 0.634842" mass="4.962" diaginertia="0.0480229 0.0462788 0.00887409"/>
            <joint name="right_hip_roll_joint" pos="0 0 0" axis="1 0 0" range="-3.14 0.43" actuatorfrcrange="-200 200"/>
            <geom type="mesh" contype="0" conaffinity="0" group="1" density="0" rgba="0.1 0.1 0.1 1" mesh="right_hip_roll_link"/>
            <body name="right_knee_link" pos="0 0 -0.4">
              <inertial pos="0.000179 -0.000121 -0.168936" quat="0.909021 0.00514003 0.0104983 0.416585" mass="3.839" diaginertia="0.0391044 0.038959 0.00501125"/>
              <joint name="right_knee_joint" pos="0 0 0" axis="0 1 0" range="-0.12 2.19" actuatorfrcrange="-300 300"/>
              <geom type="mesh" contype="0" conaffinity="0" group="1" density="0" rgba="0.1 0.1 0.1 1" mesh="right_knee_link"/>
              <body name="right_ankle_pitch_link" pos="0 0 -0.4">
                <inertial pos="-0.000294 0 -0.010794" quat="0.999984 0 -0.00574445 0" mass="0.102" diaginertia="2.39454e-05 2.1837e-05 1.34126e-05"/>
                <joint name="right_ankle_pitch_joint" pos="0 0 0" axis="0 1 0" range="-0.897334 0.523598" actuatorfrcrange="-60 60"/>
                <geom type="mesh" contype="0" conaffinity="0" group="1" density="0" rgba="0.1 0.1 0.1 1" mesh="right_ankle_pitch_link"/>
                <body name="right_ankle_roll_link" pos="0 0 -0.02">
                  <inertial pos="0.029589 0 -0.015973" quat="0 0.725858 0 0.687845" mass="0.747" diaginertia="0.00359178 0.00343534 0.000640307"/>
                  <joint name="right_ankle_roll_joint" pos="0 0 0" axis="1 0 0" range="-0.261799 0.261799" actuatorfrcrange="-40 40"/>
                  <geom type="mesh" contype="0" conaffinity="0" group="1" density="0" rgba="0.1 0.1 0.1 1" mesh="right_ankle_roll_link"/>
                  <geom type="mesh" rgba="0.1 0.1 0.1 1" mesh="right_ankle_roll_link"/>
                </body>
              </body>
            </body>
          </body>
        </body>
      </body>
      <body name="torso_link">
        <inertial pos="0.000489 0.002797 0.20484" quat="0.999989 -0.00130808 -0.00282289 -0.00349105" mass="17.789" diaginertia="0.487315 0.409628 0.127837"/>
        <joint name="torso_joint" pos="0 0 0" axis="0 0 1" range="-2.35 2.35" actuatorfrcrange="-200 200"/>
        <geom type="mesh" contype="0" conaffinity="0" group="1" density="0" rgba="0.1 0.1 0.1 1" mesh="torso_link"/>
        <geom type="mesh" contype="0" conaffinity="0" group="1" density="0" rgba="1 1 1 1" mesh="logo_link"/>
        <site name="imu" size="0.01" pos="-0.04452 -0.01891 0.27756"/>
        <body name="left_shoulder_pitch_link" pos="0 0.14806 0.42333" quat="0.991445 0.130526 0 0">
          <inertial pos="0.003053 0.06042 -0.0059" quat="0.761799 0.645681 -0.0378496 -0.0363943" mass="1.327" diaginertia="0.000588757 0.00053309 0.000393023"/>
          <joint name="left_shoulder_pitch_joint" pos="0 0 0" axis="0 1 0" range="-3.14 1.57" actuatorfrcrange="-40 40"/>
          <geom type="mesh" contype="0" conaffinity="0" group="1" density="0" rgba="0.1 0.1 0.1 1" mesh="left_shoulder_pitch_link"/>
          <body name="left_shoulder_roll_link" pos="0.0342 0.061999 -0.0060011" quat="0.991445 -0.130526 0 0">
            <inertial pos="-0.030932 -1e-06 -0.10609" quat="0.986055 0.000456937 0.166408 0.00213553" mass="1.393" diaginertia="0.00200869 0.00193464 0.000449847"/>
            <joint name="left_shoulder_roll_joint" pos="0 0 0" axis="1 0 0" range="-0.38 3.4" actuatorfrcrange="-40 40"/>
            <geom type="mesh" contype="0" conaffinity="0" group="1" density="0" rgba="0.1 0.1 0.1 1" mesh="left_shoulder_roll_link"/>
            <body name="left_shoulder_yaw_link" pos="-0.0342 0 -0.1456">
              <inertial pos="0.004583 0.001128 -0.001128" quat="0.663644 -0.0108866 -0.0267235 0.747492" mass="1.505" diaginertia="0.00431782 0.00420697 0.000645658"/>
              <joint name="left_shoulder_yaw_joint" pos="0 0 0" axis="0 0 1" range="-2.66 3.01" actuatorfrcrange="-18 18"/>
              <geom type="mesh" contype="0" conaffinity="0" group="1" density="0" rgba="0.1 0.1 0.1 1" mesh="left_shoulder_yaw_link"/>
              <body name="left_elbow_link" pos="0.006 0.0329 -0.182">
                <inertial pos="0.077092 -0.028751 -0.009714" quat="0.544921 0.610781 0.423352 0.388305" mass="0.691" diaginertia="0.000942091 0.000905273 0.00023025"/>
                <joint name="left_elbow_joint" pos="0 0 0" axis="0 1 0" range="-0.95 3.18" actuatorfrcrange="-18 18"/>
                <geom type="mesh" contype="0" conaffinity="0" group="1" density="0" rgba="0.1 0.1 0.1 1" mesh="left_elbow_link"/>
                <body name="left_wrist_roll_link" pos="0.121 -0.0329 -0.011">
                  <inertial pos="0.035281 -0.00232 0.000337" quat="0.334998 0.622198 -0.240131 0.66557" mass="0.683" diaginertia="0.00034681 0.000328248 0.000294628"/>
                  <joint name="left_wrist_roll_joint" pos="0 0 0" axis="1 0 0" range="-3.01 2.75" actuatorfrcrange="-19 19"/>
                  <geom type="mesh" contype="0" conaffinity="0" group="1" density="0" rgba="0.1 0.1 0.1 1" mesh="left_wrist_roll_link"/>
                  <body name="left_wrist_pitch_link" pos="0.087 0 0">
                    <inertial pos="0.020395 3.6e-05 -0.002973" quat="0.915893 -0.228405 -0.327262 -0.0432527" mass="0.484" diaginertia="7.25675e-05 7.00325e-05 6.9381e-05"/>
                    <joint name="left_wrist_pitch_joint" pos="0 0 0" axis="0 1 0" range="-0.4625 0.4625" actuatorfrcrange="-19 19"/>
                    <geom type="mesh" contype="0" conaffinity="0" group="1" density="0" rgba="0.1 0.1 0.1 1" mesh="left_wrist_pitch_link"/>
                    <body name="left_wrist_yaw_link" pos="0.02 0 0">
                      <inertial pos="0.027967 9.6e-05 0.000739" quat="0.704961 -0.0198461 -0.019614 0.708697" mass="0.124" diaginertia="0.000169999 0.000137463 8.46436e-05"/>
                      <joint name="left_wrist_yaw_joint" pos="0 0 0" axis="0 0 1" range="-1.27 1.27" actuatorfrcrange="-19 19"/>
                      <geom type="mesh" contype="0" conaffinity="0" group="1" density="0" rgba="0.1 0.1 0.1 1" mesh="wrist_yaw_link"/>
                      <site name="left_hand" pos="0.17 0 0" size="0.01" rgba="0 1 0 1"/>

                      <geom type="mesh" contype="0" conaffinity="0" group="2" density="0" pos="0.054 0 0" quat="0.7071068 0.0 0.70710685 0.0" mesh="h12_mount"/>
                      <geom name="h12_collision_L" size="0.032 0.0125" pos="0.0665 0 0" quat="0.7071068 0.0 0.70710685 0.0" density="0" type="cylinder" class="collision"/>
                      <body name="gripper_attachment_L" gravcomp="1" pos="0.079 0 -0.003125" quat="0.7071068 0.0 0.70710685 0.0">
                        <include file="magpie/magpie_gripper_left.xml"/>
                      </body>

                    </body>
                  </body>
                </body>
              </body>
            </body>
          </body>
        </body>
        <body name="right_shoulder_pitch_link" pos="0 -0.14806 0.42333" quat="0.991445 -0.130526 0 0">
          <inertial pos="0.003053 -0.06042 -0.0059" quat="0.645681 0.761799 0.0363943 0.0378496" mass="1.327" diaginertia="0.000588757 0.00053309 0.000393023"/>
          <joint name="right_shoulder_pitch_joint" pos="0 0 0" axis="0 1 0" range="-3.14 1.57" actuatorfrcrange="-40 40"/>
          <geom type="mesh" contype="0" conaffinity="0" group="1" density="0" rgba="0.1 0.1 0.1 1" mesh="right_shoulder_pitch_link"/>
          <body name="right_shoulder_roll_link" pos="0.0342 -0.061999 -0.0060011" quat="0.991445 0.130526 0 0">
            <inertial pos="-0.030932 1e-06 -0.10609" quat="0.986055 -0.000456937 0.166408 -0.00213553" mass="1.393" diaginertia="0.00200869 0.00193464 0.000449847"/>
            <joint name="right_shoulder_roll_joint" pos="0 0 0" axis="1 0 0" range="-3.4 0.38" actuatorfrcrange="-40 40"/>
            <geom type="mesh" contype="0" conaffinity="0" group="1" density="0" rgba="0.1 0.1 0.1 1" mesh="right_shoulder_roll_link"/>
            <body name="right_shoulder_yaw_link" pos="-0.0342 0 -0.1456">
              <inertial pos="0.004583 -0.001128 -0.001128" quat="0.747492 -0.0267235 -0.0108866 0.663644" mass="1.505" diaginertia="0.00431782 0.00420697 0.000645658"/>
              <joint name="right_shoulder_yaw_joint" pos="0 0 0" axis="0 0 1" range="-3.01 2.66" actuatorfrcrange="-18 18"/>
              <geom type="mesh" contype="0" conaffinity="0" group="1" density="0" rgba="0.1 0.1 0.1 1" mesh="right_shoulder_yaw_link"/>
              <body name="right_elbow_link" pos="0.006 -0.0329 -0.182">
                <inertial pos="0.077092 0.028751 -0.009714" quat="0.388305 0.423352 0.610781 0.544921" mass="0.691" diaginertia="0.000942091 0.000905273 0.00023025"/>
                <joint name="right_elbow_joint" pos="0 0 0" axis="0 1 0" range="-0.95 3.18" actuatorfrcrange="-18 18"/>
                <geom type="mesh" contype="0" conaffinity="0" group="1" density="0" rgba="0.1 0.1 0.1 1" mesh="right_elbow_link"/>
                <body name="right_wrist_roll_link" pos="0.121 0.0329 -0.011">
                  <inertial pos="0.035281 -0.00232 0.000337" quat="0.334998 0.622198 -0.240131 0.66557" mass="0.683" diaginertia="0.00034681 0.000328248 0.000294628"/>
                  <joint name="right_wrist_roll_joint" pos="0 0 0" axis="1 0 0" range="-2.75 3.01" actuatorfrcrange="-19 19"/>
                  <geom type="mesh" contype="0" conaffinity="0" group="1" density="0" rgba="0.1 0.1 0.1 1" mesh="right_wrist_roll_link"/>
                  <body name="right_wrist_pitch_link" pos="0.087 0 0">
                    <inertial pos="0.020395 3.6e-05 -0.002973" quat="0.915893 -0.228405 -0.327262 -0.0432527" mass="0.484" diaginertia="7.25675e-05 7.00325e-05 6.9381e-05"/>
                    <joint name="right_wrist_pitch_joint" pos="0 0 0" axis="0 1 0" range="-0.4625 0.4625" actuatorfrcrange="-19 19"/>
                    <geom type="mesh" contype="0" conaffinity="0" group="1" density="0" rgba="0.1 0.1 0.1 1" mesh="right_wrist_pitch_link"/>
                    <body name="right_wrist_yaw_link" pos="0.02 0 0">
                      <inertial pos="0.027967 -9.6e-05 0.000739" quat="0.708697 -0.019614 -0.0198461 0.704961" mass="0.124" diaginertia="0.000169999 0.000137463 8.46436e-05"/>
                      <joint name="right_wrist_yaw_joint" pos="0 0 0" axis="0 0 1" range="-1.27 1.27" actuatorfrcrange="-19 19"/>
                      <geom type="mesh" contype="0" conaffinity="0" group="1" density="0" rgba="0.1 0.1 0.1 1" mesh="wrist_yaw_link"/>
                      <site name="right_hand" pos="0.17 0 0" size="0.01" rgba="0 1 0 1"/>

                      <geom type="mesh" contype="0" conaffinity="0" group="2" density="0" pos="0.054 0 0" quat="0.7071068 0.0 0.70710685 0.0" mesh="h12_mount"/>
                      <geom name="h12_collision" size="0.032 0.0125" pos="0.0665 0 0" quat="0.7071068 0.0 0.70710685 0.0" density="0" type="cylinder" class="collision"/>
                      <body name="gripper_attachment" gravcomp="1" pos="0.079 0 -0.003125" quat="0.7071068 0.0 0.70710685 0.0">
                        <include file="magpie/magpie_gripper.xml"/>
                      </body>

                    </body>
                  </body>
                </body>
              </body>
            </body>
          </body>
        </body>
      </body>
    </body>
  </worldbody>

  <!-- Finger 4-bar coupling constraints -->
  <equality>
    <connect name="left_4bar_close" active="true" body1="base_top" body2="left_rocker"
             anchor="-0.00075 0.060 0.065" solref="0.005 1" solimp="0.95 0.99 0.001"/>
    <connect name="right_4bar_close" active="true" body1="base_top" body2="right_rocker"
             anchor="-0.00075 -0.060 0.065" solref="0.005 1" solimp="0.95 0.99 0.001"/>
    <connect name="leftg_left_4bar_close" active="true" body1="leftg_base_top" body2="leftg_left_rocker"
             anchor="-0.00075 0.060 0.065" solref="0.005 1" solimp="0.95 0.99 0.001"/>
    <connect name="leftg_right_4bar_close" active="true" body1="leftg_base_top" body2="leftg_right_rocker"
             anchor="-0.00075 -0.060 0.065" solref="0.005 1" solimp="0.95 0.99 0.001"/>
  </equality>

  <actuator>
    <!-- H12 body actuators matched to fame_h1_2_handless.xml for RL policy compatibility -->
    <motor name="left_hip_yaw_joint" joint="left_hip_yaw_joint" ctrlrange="-200 200"/>
    <motor name="left_hip_pitch_joint" joint="left_hip_pitch_joint" ctrlrange="-200 200"/>
    <motor name="left_hip_roll_joint" joint="left_hip_roll_joint" ctrlrange="-200 200"/>
    <motor name="left_knee_joint" joint="left_knee_joint" ctrlrange="-300 300"/>
    <motor name="left_ankle_pitch_joint" joint="left_ankle_pitch_joint" ctrlrange="-60 60"/>
    <motor name="left_ankle_roll_joint" joint="left_ankle_roll_joint" ctrlrange="-40 40"/>
    <motor name="right_hip_yaw_joint" joint="right_hip_yaw_joint" ctrlrange="-200 200"/>
    <motor name="right_hip_pitch_joint" joint="right_hip_pitch_joint" ctrlrange="-200 200"/>
    <motor name="right_hip_roll_joint" joint="right_hip_roll_joint" ctrlrange="-200 200"/>
    <motor name="right_knee_joint" joint="right_knee_joint" ctrlrange="-300 300"/>
    <motor name="right_ankle_pitch_joint" joint="right_ankle_pitch_joint" ctrlrange="-60 60"/>
    <motor name="right_ankle_roll_joint" joint="right_ankle_roll_joint" ctrlrange="-40 40"/>
    <motor name="torso_joint" joint="torso_joint" ctrlrange="-200 200"/>
    <motor name="left_shoulder_pitch_joint" joint="left_shoulder_pitch_joint" ctrlrange="-40 40"/>
    <motor name="left_shoulder_roll_joint" joint="left_shoulder_roll_joint" ctrlrange="-40 40"/>
    <motor name="left_shoulder_yaw_joint" joint="left_shoulder_yaw_joint" ctrlrange="-18 18"/>
    <motor name="left_elbow_joint" joint="left_elbow_joint" ctrlrange="-18 18"/>
    <motor name="left_wrist_roll_joint" joint="left_wrist_roll_joint" ctrlrange="-19 19"/>
    <motor name="left_wrist_pitch_joint" joint="left_wrist_pitch_joint" ctrlrange="-19 19"/>
    <motor name="left_wrist_yaw_joint" joint="left_wrist_yaw_joint" ctrlrange="-19 19"/>
    <motor name="right_shoulder_pitch_joint" joint="right_shoulder_pitch_joint" ctrlrange="-40 40"/>
    <motor name="right_shoulder_roll_joint" joint="right_shoulder_roll_joint" ctrlrange="-40 40"/>
    <motor name="right_shoulder_yaw_joint" joint="right_shoulder_yaw_joint" ctrlrange="-18 18"/>
    <motor name="right_elbow_joint" joint="right_elbow_joint" ctrlrange="-18 18"/>
    <motor name="right_wrist_roll_joint" joint="right_wrist_roll_joint" ctrlrange="-19 19"/>
    <motor name="right_wrist_pitch_joint" joint="right_wrist_pitch_joint" ctrlrange="-19 19"/>
    <motor name="right_wrist_yaw_joint" joint="right_wrist_yaw_joint" ctrlrange="-19 19"/>

    <position name="left_finger_actuator" joint="left_hinge_1" ctrlrange="-0.035 2.70" kp="10"/>
    <position name="right_finger_actuator" joint="right_hinge_1" ctrlrange="-2.70 0.035" kp="10"/>
    <position name="left_finger_actuator_L" joint="leftg_left_hinge_1" ctrlrange="-0.035 2.70" kp="10"/>
    <position name="right_finger_actuator_L" joint="leftg_right_hinge_1" ctrlrange="-2.70 0.035" kp="10"/>
  </actuator>

  <contact>
    <exclude body1="torso_link" body2="left_shoulder_roll_link"/>
    <exclude body1="torso_link" body2="right_shoulder_roll_link"/>
  </contact>

  <sensor>
    <gyro name="imu-angular-velocity" site="imu" noise="5e-4" cutoff="34.9"/>
    <accelerometer name="imu-linear-acceleration" site="imu" noise="1e-2" cutoff="157"/>
  </sensor>

</mujoco>
