<mujoco model="magpie_gripper">
    <default>
        <geom type="mesh" xyaxes="0 -1 0 1 0 0"/>
    </default>

    <asset>
        <mesh name="base_bot" file="assets/base_bot.stl" scale="0.001 0.001 0.001"/>
        <mesh name="base_top" file="assets/base_top.stl" scale="0.001 0.001 0.001"/>
        <mesh name="left_coupler_bot" file="assets/left_coupler_bot.stl" scale="0.001 0.001 0.001"/>
        <mesh name="left_coupler_top" file="assets/left_coupler_top.stl" scale="0.001 0.001 0.001"/>
        <mesh name="right_coupler_bot" file="assets/right_coupler_bot.stl" scale="0.001 0.001 0.001"/>
        <mesh name="right_coupler_top" file="assets/right_coupler_top.stl" scale="0.001 0.001 0.001"/>
        <mesh name="left_rocker" file="assets/left_rocker.stl" scale="0.001 0.001 0.001"/>
        <mesh name="right_rocker" file="assets/right_rocker.stl" scale="0.001 0.001 0.001"/>
        <mesh name="left_crank" file="assets/left_crank.stl" scale="0.001 0.001 0.001"/>
        <mesh name="right_crank" file="assets/right_crank.stl" scale="0.001 0.001 0.001"/>
        <mesh name="left_finger" file="assets/left_finger.stl" scale="0.001 0.001 0.001"/>
        <mesh name="left_finger_combined" file="assets/left_finger_combined.stl" scale="0.001 0.001 0.001"/>
        <mesh name="right_finger" file="assets/right_finger.stl" scale="0.001 0.001 0.001"/>
        <mesh name="right_finger_combined" file="assets/right_finger_combined.stl" scale="0.001 0.001 0.001"/>
        <mesh name="mount" file="assets/mount.stl" scale="0.001 0.001 0.001"/>
    </asset>
    <worldbody>
        <!-- <geom type="plane" size="10 10 0.1" pos="0 0 -2" rgba=".9 0 0 1" /> -->
        <!-- <light diffuse=".5 .5 .5" pos="0 0 3" dir="0 0 -1" /> -->
        <body name="mount">
        <geom mesh="mount"/>
            <body name="base_bot">
                <geom mesh="base_bot"/>
                <body name="base_top">
                    <geom mesh="base_top"/>

                    <body name="left_crank">
                        <joint name="left_hinge_1" pos="1.75 -38.0 69.0" axis="1 0 0"/>
                        <geom mesh="left_crank"/>
                        <body name="left_rocker">
                            <!-- <joint name="left_hinge_2" pos="" axis=""/> -->
                            <geom mesh="left_rocker"/>
                            <body name="left_finger_combined">
                                <!-- <joint name="left_hinge_3" pos="" axis=""/> -->
                                <geom mesh="left_finger_combined"/>
                            </body>
                        </body>
                    </body>

                    <body name="right_crank">
                        <!-- <joint name="right_hinge_1" pos="" axis=""/> -->
                        <geom mesh="right_crank"/>
                        <body name="right_rocker">
                            <!-- <joint name="right_hinge_2" pos="" axis=""/> -->
                            <geom mesh="right_rocker"/>
                            <body name="right_finger_combined">
                                <!-- <joint name="right_hinge_3" pos="" axis=""/> -->
                                <geom mesh="right_finger_combined"/>
                            </body>
                        </body>
                    </body>

                </body>
            </body>
        </body>
    </worldbody>
    <equality>
        <!-- <connect name="left_kinematic_link" active="true" body1="base_top" body2="left_finger_combined" anchor="" /> -->
        <!-- <connect name="right_kinematic_link" active="true" body1="base_top" body2="right_finger_combined" anchor="" /> -->
    </equality>
</mujoco>
