<mujoco model="inspire_hand_left">
  <compiler angle="radian" meshdir="assets" />

  <visual>
    <headlight ambient=".4 .4 .4" diffuse=".8 .8 .8" specular="0.1 0.1 0.1"/>
    <map znear=".01"/>
    <quality shadowsize="2048"/>
    <global elevation="-15"/>
  </visual>

  <default>
    <default class="inspire">
      <position kp="100" dampratio="1.0" />
      <joint damping="0.1" armature="0.01" frictionloss="0.001" />
      <material specular="0.5" shininess="0.25" />
        <default class="visual">
          <geom type="mesh" contype="0" conaffinity="0" group="2" rgba="0.1 0.1 0.1 1"/>
        </default>
        <default class="collision">
          <geom type="mesh" group="3" condim="4" friction="1 0.005 0.001" solref="0.002 1" solimp="0.9 0.95 0.001" />
          <default class="eef_collision">
            <geom type="cylinder" />
          </default>
        </default>
     <site size="0.0035" type="sphere" rgba="1 0 0 1" group="3" />
    </default>
  </default>

  <asset>
    <material class="inspire" name="black" rgba="0.033 0.033 0.033 1" />
    <material class="inspire" name="jointgray" rgba="0.278 0.278 0.278 1" />
    <material class="inspire" name="linkgray" rgba="0.82 0.82 0.82 1" />
    <texture name="blue_grid" type="2d" builtin="checker" rgb1=".02 .14 .44" rgb2=".27 .55 1" width="300" height="300" mark="edge" markrgb="1 1 1"/>
    <material name="blue_grid" texture="blue_grid" texrepeat="1 1" texuniform="true" reflectance=".2"/>
    <texture name="grey_grid" type="2d" builtin="checker" rgb1=".26 .26 .26" rgb2=".6 .6 .6" width="300" height="300" mark="edge" markrgb="1 1 1"/>
    <material name="grey_grid" texture="grey_grid" texrepeat="1 1" texuniform="true" reflectance=".2"/>
    <texture name="skybox" type="skybox" builtin="gradient" rgb1=".66 .79 1" rgb2=".9 .91 .93" width="800" height="800"/>

    <mesh name="ur5_mount" content_type="model/stl" file="ur5_mount.stl"/>

    <mesh name="left_thumb_proximal_base" content_type="model/stl" file="collision/left_thumb_proximal_base.stl" />
    <mesh name="left_thumb_proximal" content_type="model/stl" file="collision/left_thumb_proximal.stl" />
    <mesh name="left_thumb_intermediate" content_type="model/stl" file="collision/left_thumb_intermediate.stl" />
    <mesh name="left_thumb_distal" content_type="model/stl" file="collision/left_thumb_distal.stl" />
    <mesh name="left_index_proximal" content_type="model/stl" file="collision/left_index_proximal.stl" />
    <mesh name="left_index_intermediate" content_type="model/stl" file="collision/left_index_intermediate.stl" />
    <mesh name="left_middle_intermediate" content_type="model/stl" file="collision/left_middle_intermediate.stl" />
    <mesh name="left_pinky_intermediate" content_type="model/stl" file="collision/left_pinky_intermediate.stl" />

    <!-- <mesh name="left_base_link_visual" file="visual/left_base_link_visual.stl"/> -->
    <mesh name="left_base_link_visual" file="visual/L_hand_base_link.STL"/>
    <mesh name="left_thumb_proximal_base_visual" content_type="model/stl" file="visual/left_thumb_proximal_base_visual.stl" />
    <mesh name="left_thumb_proximal_visual" content_type="model/stl" file="visual/left_thumb_proximal_visual.stl" />
    <mesh name="left_thumb_intermediate_visual" content_type="model/stl" file="visual/left_thumb_intermediate_visual.stl" />
    <mesh name="left_thumb_distal_visual" content_type="model/stl" file="visual/left_thumb_distal_visual.stl" />
    <mesh name="left_index_proximal_visual" content_type="model/stl" file="visual/left_index_proximal_visual.stl" />
    <mesh name="left_index_intermediate_visual" content_type="model/stl" file="visual/left_index_intermediate_visual.stl" />
    <mesh name="left_middle_intermediate_visual" content_type="model/stl" file="visual/left_middle_intermediate_visual.stl" />
    <mesh name="left_pinky_intermediate_visual" content_type="model/stl" file="visual/left_pinky_intermediate_visual.stl" />
  </asset>
  <worldbody>
    <light name="spotlight" mode="targetbodycom" target="thumb_proximal_base" pos="0 -1 2" />
    <geom type="mesh" contype="0" conaffinity="0" group="1" pos="0 0 -0.005" quat="0 0 0.7071068 0.7071068" density="0" mesh="ur5_mount" />
    <body name="base" childclass="inspire">
      <geom type="mesh" quat="9.38189e-07 -9.38183e-07 -0.707105 0.707109" mesh="left_base_link_visual" class="visual"/>
      <geom size="0.028 0.0139" pos="0 3.64411e-10 0.0136" quat="1.32679e-06 -4.1794e-12 -3.15e-06 1" type="cylinder" class="collision" />
      <geom size="0.01955 0.0101 0.0287" pos="0.0032 -7.47328e-09 0.038" quat="9.38186e-07 -9.38186e-07 -0.707107 0.707107" type="box" class="collision" />
      <geom size="0.01955 0.02 0.0407" pos="0.0032 -6.66408e-09 0.0682" quat="9.38186e-07 -9.38186e-07 -0.707107 0.707107" type="box" class="collision" />
      <geom size="0.0161 0.02 0.0407" pos="0 2.89653e-09 0.1081" quat="9.38186e-07 -9.38186e-07 -0.707107 0.707107" type="box" class="collision" />
      <geom size="0.00625 0.00555 0.00445" pos="0.00160008 0.0309 0.134" quat="9.38186e-07 -9.38186e-07 -0.707107 0.707107" type="box" class="collision" />
      <geom size="0.00625 0.00555 0.00445" pos="0.00160003 0.0118 0.134" quat="9.38186e-07 -9.38186e-07 -0.707107 0.707107" type="box" class="collision" />
      <geom size="0.00625 0.00555 0.00445" pos="0.00159998 -0.007 0.134" quat="9.38186e-07 -9.38186e-07 -0.707107 0.707107" type="box" class="collision" />
      <geom size="0.00625 0.00555 0.00445" pos="0.00159993 -0.0262 0.134" quat="9.38186e-07 -9.38186e-07 -0.707107 0.707107" type="box" class="collision" />
      <body name="thumb_proximal_base" pos="0.0169599 -0.02045 0.0691" quat="-0.707107 -1.2892e-06 1.30815e-06 0.707106">
        <inertial pos="0.0048817 0.0009382 -0.00722" quat="0.408023 0.323596 0.515015 0.680854" mass="0.0018869" diaginertia="8.66026e-08 6.8732e-08 4.94194e-08" />
        <joint name="thumb_proximal_yaw_joint" pos="0 0 0" axis="0 0 1" range="0 1.308" actuatorfrcrange="-1 1" />
        <geom type="mesh" mesh="left_thumb_proximal_base" class="collision" />
        <geom class="visual" mesh="left_thumb_proximal_base_visual" />
        <body name="thumb_proximal" pos="0.0099867 0.0098242 -0.0089" quat="0.704571 -0.704573 -0.0598169 0.0598167">
          <inertial pos="0.021932 -0.012785 -0.0080386" quat="0.254474 0.660716 -0.251893 0.659733" mass="0.0066075" diaginertia="2.78601e-06 2.43933e-06 8.64566e-07" />
          <joint name="thumb_proximal_pitch_joint" pos="0 0 0" axis="0 0 -1" range="0 0.6" actuatorfrcrange="-1 1" />
          <geom type="mesh" mesh="left_thumb_proximal" class="collision" />
          <geom class="visual" mesh="left_thumb_proximal_visual" />
          <body name="thumb_intermediate" pos="0.04407 -0.034553 -0.0008">
            <inertial pos="0.0095544 0.0016282 -0.0071997" quat="0.307389 0.636718 -0.307548 0.636802" mass="0.0037847" diaginertia="4.6531e-07 4.48089e-07 2.45661e-07" />
            <joint name="thumb_intermediate_joint" pos="0 0 0" axis="0 0 -1" range="0 0.8" actuatorfrcrange="-1 1" />
            <geom type="mesh" mesh="left_thumb_intermediate" class="collision" />
            <geom class="visual" mesh="left_thumb_intermediate_visual" />
            <body name="thumb_distal" pos="0.020248 -0.010156 -0.0012">
              <inertial pos="0.0092888 -0.0049529 -0.0060033" quat="0.266294 0.655967 -0.262806 0.655537" mass="0.0033441" diaginertia="2.0026e-07 1.95247e-07 8.1593e-08" />
              <joint name="thumb_distal_joint" pos="0 0 0" axis="0 0 -1" range="0 0.4" actuatorfrcrange="-1 1" />
              <geom type="mesh" mesh="left_thumb_distal" class="collision" />
              <geom class="visual" mesh="left_thumb_distal_visual" />
              <site name="left_thumb_tip" pos="0.0159104 0.0156076 -0.00599021" />
              <site name="track_hand_left_thumb_tip"
                pos="0.0159104 0.0156076 -0.00599021" />
              <site name="trace_hand_left_thumb_tip"
                pos="0.0159104 0.0156076 -0.00599021" />
            </body>
          </body>
        </body>
      </body>
      <body name="index_proximal" pos="-0.000285416 -0.032268 0.13653" quat="9.21669e-07 -9.54417e-07 -0.71934 0.694658">
        <inertial pos="0.0012259 -0.011942 -0.0060001" quat="0.49121 0.50867 -0.491172 0.508643" mass="0.0042403" diaginertia="6.9398e-07 6.62871e-07 2.10909e-07" />
        <joint name="index_proximal_joint" pos="0 0 0" axis="0 0 -1" range="0 1.47" actuatorfrcrange="-1 1" />
        <geom type="mesh" mesh="left_index_proximal" class="collision" />
        <geom class="visual" mesh="left_index_proximal_visual" />
        <body name="index_intermediate" pos="-0.0026138 -0.032026 -0.001">
          <inertial pos="0.0019697 -0.019589 -0.005" quat="0.531152 0.466773 -0.531153 0.466773" mass="0.0045683" diaginertia="7.8179e-07 7.72465e-07 8.47212e-08" />
          <joint name="index_intermediate_joint" pos="0 0 0" axis="0 0 -1" range="-0.04545 1.56" actuatorfrcrange="-1 1" />
          <geom type="mesh" mesh="left_index_intermediate" class="collision" />
          <geom class="visual" mesh="left_index_intermediate_visual" />
          <site name="left_index_tip" pos="-0.00412053 0.0433132 -0.00501047" />
          <site name="track_hand_left_index_tip"
            pos="-0.00412053 0.0433132 -0.00501047" />
          <site name="trace_hand_left_index_tip"
            pos="-0.00412053 0.0433132 -0.00501047" />
        </body>
      </body>
      <body name="middle_proximal" pos="-0.000285364 -0.01295 0.1371" quat="9.38186e-07 -9.38186e-07 -0.707107 0.707107">
        <inertial pos="0.001297 -0.011934 -0.0060001" quat="0.489693 0.510131 -0.489653 0.510105" mass="0.0042403" diaginertia="6.9397e-07 6.62865e-07 2.10915e-07" />
        <joint name="middle_proximal_joint" pos="0 0 0" axis="0 0 -1" range="0 1.47" actuatorfrcrange="-1 1" />
        <geom type="mesh" mesh="left_index_proximal" class="collision" />
        <geom class="visual" mesh="left_index_proximal_visual" />
        <body name="middle_intermediate" pos="-0.0024229 -0.032041 -0.001">
          <inertial pos="0.001921 -0.020796 -0.005" quat="0.531627 0.466148 -0.531705 0.466229" mass="0.0050396" diaginertia="9.8384e-07 9.73279e-07 9.14014e-08" />
          <joint name="middle_intermediate_joint" pos="0 0 0" axis="0 0 -1" range="-0.04545 1.56" actuatorfrcrange="-1 1" />
          <geom type="mesh" mesh="left_middle_intermediate" class="collision" />
          <geom class="visual" mesh="left_middle_intermediate_visual" />
          <site name="left_middle_tip" pos="-0.00426879 0.0466043 -0.00498678" />
          <site name="track_hand_left_middle_tip"
            pos="-0.00426879 0.0466043 -0.00498678" />
          <site name="trace_hand_left_middle_tip"
            pos="-0.00426879 0.0466043 -0.00498678" />
        </body>
      </body>
      <body name="ring_proximal" pos="-0.000285313 0.0062872 0.13691" quat="9.62423e-07 -9.13305e-07 -0.688355 0.725374">
        <inertial pos="0.001297 -0.011934 -0.0060002" quat="0.489691 0.510129 -0.489654 0.510107" mass="0.0042403" diaginertia="6.9397e-07 6.62865e-07 2.10915e-07" />
        <joint name="ring_proximal_joint" pos="0 0 0" axis="0 0 -1" range="0 1.47" actuatorfrcrange="-1 1" />
        <geom type="mesh" mesh="left_index_proximal" class="collision" />
        <geom class="visual" mesh="left_index_proximal_visual" />
        <body name="ring_intermediate" pos="-0.0024229 -0.032041 -0.001">
          <inertial pos="0.0021753 -0.019567 -0.005" quat="0.528695 0.469554 -0.528695 0.469554" mass="0.0045683" diaginertia="7.8177e-07 7.72448e-07 8.4722e-08" />
          <joint name="ring_intermediate_joint" pos="0 0 0" axis="0 0 -1" range="-0.04545 1.56" actuatorfrcrange="-1 1" />
          <geom type="mesh" mesh="left_index_intermediate" class="collision" />
          <geom class="visual" mesh="left_index_intermediate_visual" />
          <site name="left_ring_tip" pos="-0.00366554 0.0433541 -0.00501047" />
          <site name="track_hand_left_ring_tip"
            pos="-0.00366554 0.0433541 -0.00501047" />
          <site name="trace_hand_left_ring_tip"
            pos="-0.00366554 0.0433541 -0.00501047" />
        </body>
      </body>
      <body name="pinky_proximal" pos="-0.000285262 0.025488 0.13571" quat="9.86001e-07 -8.87799e-07 -0.669131 0.743145">
        <inertial pos="0.001297 -0.011934 -0.0060001" quat="0.489693 0.51013 -0.489653 0.510106" mass="0.0042403" diaginertia="6.9397e-07 6.62865e-07 2.10915e-07" />
        <joint name="pinky_proximal_joint" pos="0 0 0" axis="0 0 -1" range="0 1.47" actuatorfrcrange="-1 1" />
        <geom type="mesh" mesh="left_index_proximal" class="collision" />
        <geom class="visual" mesh="left_index_proximal_visual" />
        <body name="pinky_intermediate" pos="-0.0024229 -0.032041 -0.001">
          <inertial pos="0.0024748 -0.016203 -0.0050031" quat="0.528862 0.47398 -0.524799 0.469291" mass="0.0035996" diaginertia="4.4867e-07 4.43723e-07 6.56538e-08" />
          <joint name="pinky_intermediate_joint" pos="0 0 0" axis="0 0 -1" range="-0.04545 1.56" actuatorfrcrange="-1 1" />
          <geom type="mesh" mesh="left_pinky_intermediate" class="collision" />
          <geom class="visual" mesh="left_pinky_intermediate_visual" />
          <site name="left_pinky_tip" pos="-0.00260734 0.0362776 -0.00501047" />
          <site name="track_hand_left_pinky_tip"
            pos="-0.00260734 0.0362776 -0.00501047" />
          <site name="trace_hand_left_pinky_tip"
            pos="-0.00260734 0.0362776 -0.00501047" />
        </body>
      </body>
    </body>
  </worldbody>

  <contact>
    <!-- Palm to finger proximal exclusions -->
    <exclude body1="base" body2="thumb_proximal_base"/>
    <exclude body1="base" body2="index_proximal"/>
    <exclude body1="base" body2="middle_proximal"/>
    <exclude body1="base" body2="ring_proximal"/>
    <exclude body1="base" body2="pinky_proximal"/>
    <exclude body1="base" body2="thumb_proximal"/>

    <!-- Thumb chain exclusions -->
    <exclude body1="thumb_proximal_base" body2="thumb_intermediate"/>
    <exclude body1="thumb_proximal" body2="thumb_intermediate"/>
    <exclude body1="thumb_intermediate" body2="thumb_distal"/>

    <!-- Finger chain exclusions -->
    <exclude body1="index_proximal" body2="index_intermediate"/>
    <exclude body1="middle_proximal" body2="middle_intermediate"/>
    <exclude body1="ring_proximal" body2="ring_intermediate"/>
    <exclude body1="pinky_proximal" body2="pinky_intermediate"/>

    <!-- Cross-finger exclusions at palm level -->
    <exclude body1="index_proximal" body2="middle_proximal"/>
    <exclude body1="middle_proximal" body2="ring_proximal"/>
    <exclude body1="ring_proximal" body2="pinky_proximal"/>

    <!-- Thumb-to-index exclusion -->
    <exclude body1="thumb_proximal_base" body2="index_proximal"/>
  </contact>

  <equality>
    <joint joint1="pinky_proximal_joint" joint2="pinky_intermediate_joint" polycoef="0 1 0 0 0"/>
    <joint joint1="ring_proximal_joint" joint2="ring_intermediate_joint" polycoef="0 1 0 0 0"/>
    <joint joint1="middle_proximal_joint" joint2="middle_intermediate_joint" polycoef="0 1 0 0 0"/>
    <joint joint1="index_proximal_joint" joint2="index_intermediate_joint" polycoef="0 1 0 0 0"/>
    <joint joint1="thumb_proximal_pitch_joint" joint2="thumb_intermediate_joint" polycoef="0 1 0 0 0"/>
    <joint joint1="thumb_distal_joint" joint2="thumb_intermediate_joint" polycoef="0 1 0 0 0"/>
  </equality>

  <actuator>
    <position class="inspire" name="pinky" joint="pinky_proximal_joint" ctrlrange="0 1.47"/>
    <position class="inspire" name="ring" joint="ring_proximal_joint" ctrlrange="0 1.47"/>
    <position class="inspire" name="middle" joint="middle_proximal_joint" ctrlrange="0 1.47"/>
    <position class="inspire" name="index" joint="index_proximal_joint" ctrlrange="0 1.47"/>
    <position class="inspire" name="thumb_proximal" joint="thumb_proximal_pitch_joint" ctrlrange="0 0.6"/>
    <position class="inspire" name="thumb_yaw" joint="thumb_proximal_yaw_joint" ctrlrange="0 1.308"/>
  </actuator>

</mujoco>
