<mujoco model="inspire_hand_right">
  <compiler angle="radian" meshdir="assets" />

  <visual>
    <headlight ambient=".4 .4 .4" diffuse=".8 .8 .8" specular="0.1 0.1 0.1"/>
    <map znear=".01"/>
    <quality shadowsize="2048"/>
    <global elevation="-15"/>
  </visual>

  <default>
    <default class="inspire">
      <material specular="0.5" shininess="0.25" />
        <default class="visual">
          <geom type="mesh" contype="0" conaffinity="0" group="2" />
        </default>
        <default class="collision">
          <geom type="capsule" group="3" />
          <default class="eef_collision">
            <geom type="cylinder" />
          </default>
        </default>
    </default>
  </default>

  <asset>
    <material class="inspire" name="black" rgba="0.033 0.033 0.033 1" />
    <material class="inspire" name="jointgray" rgba="0.278 0.278 0.278 1" />
    <material class="inspire" name="linkgray" rgba="0.82 0.82 0.82 1" />
    <texture name="blue_grid" type="2d" builtin="checker" rgb1=".02 .14 .44" rgb2=".27 .55 1" width="300" height="300" mark="edge" markrgb="1 1 1"/>
    <material name="blue_grid" texture="blue_grid" texrepeat="1 1" texuniform="true" reflectance=".2"/>
    <texture name="grey_grid" type="2d" builtin="checker" rgb1=".26 .26 .26" rgb2=".6 .6 .6" width="300" height="300" mark="edge" markrgb="1 1 1"/>
    <material name="grey_grid" texture="grey_grid" texrepeat="1 1" texuniform="true" reflectance=".2"/>
    <texture name="skybox" type="skybox" builtin="gradient" rgb1=".66 .79 1" rgb2=".9 .91 .93" width="800" height="800"/>

    <!-- collision meshes -->
    <mesh name="right_thumb_proximal_base" file="collision/right_thumb_proximal_base.stl"/>
    <mesh name="right_thumb_proximal" file="collision/right_thumb_proximal.stl"/>
    <mesh name="right_thumb_intermediate" file="collision/right_thumb_intermediate.stl"/>
    <mesh name="right_thumb_distal" file="collision/right_thumb_distal.stl"/>
    <mesh name="right_index_proximal" file="collision/right_index_proximal.stl"/>
    <mesh name="right_index_intermediate" file="collision/right_index_intermediate.stl"/>
    <mesh name="right_middle_intermediate" file="collision/right_middle_intermediate.stl"/>
    <mesh name="right_pinky_intermediate" file="collision/right_pinky_intermediate.stl"/>

    <!-- visual meshes -->
    <mesh name="right_base_link_visual" file="visual/right_base_link_visual.stl"/>
    <mesh name="right_thumb_proximal_base_visual" file="visual/right_thumb_proximal_base_visual.stl" />
    <mesh name="right_thumb_proximal_visual" file="visual/right_thumb_proximal_visual.stl" />
    <mesh name="right_thumb_intermediate_visual" file="visual/right_thumb_intermediate_visual.stl" />
    <mesh name="right_thumb_distal_visual" file="visual/right_thumb_distal_visual.stl" />
    <mesh name="right_index_proximal_visual" file="visual/right_index_proximal_visual.stl" />
    <mesh name="right_index_intermediate_visual" file="visual/right_index_intermediate_visual.stl" />
    <mesh name="right_middle_intermediate_visual" file="visual/right_middle_intermediate_visual.stl" />
    <mesh name="right_pinky_intermediate_visual" file="visual/right_pinky_intermediate_visual.stl" />
  </asset>
  <worldbody>
    <light name="spotlight" mode="targetbodycom" target="base" pos="0 -1 2" />
    <body name="base" childclass="inspire">
      <geom type="mesh" quat="9.38189e-07 -9.38183e-07 -0.707105 0.707109" mesh="right_base_link_visual" class="visual"/>
      <geom size="0.028 0.0139" pos="0 8.60444e-08 0.0136" quat="1.32679e-06 0 0 1" type="cylinder" class="collision" />
      <geom size="0.01955 0.0101 0.0287" pos="0.0032 2.31927e-07 0.038" quat="9.38189e-07 -9.38183e-07 -0.707105 0.707109" type="box" class="collision" />
      <geom size="0.01955 0.02 0.0407" pos="0.0032 4.22996e-07 0.0682" quat="9.38189e-07 -9.38183e-07 -0.707105 0.707109" type="box" class="collision" />
      <geom size="0.0161 0.02 0.0407" pos="1.81486e-12 6.83927e-07 0.1081" quat="9.38189e-07 -9.38183e-07 -0.707105 0.707109" type="box" class="collision" />
      <geom size="0.00625 0.00555 0.00445" pos="0.00159992 -0.0308992 0.134" quat="9.38189e-07 -9.38183e-07 -0.707105 0.707109" type="box" class="collision" />
      <geom size="0.00625 0.00555 0.00445" pos="0.00159997 -0.0117992 0.134" quat="9.38189e-07 -9.38183e-07 -0.707105 0.707109" type="box" class="collision" />
      <geom size="0.00625 0.00555 0.00445" pos="0.00160002 0.00700084 0.134" quat="9.38189e-07 -9.38183e-07 -0.707105 0.707109" type="box" class="collision" />
      <geom size="0.00625 0.00555 0.00445" pos="0.00160007 0.0262008 0.134" quat="9.38189e-07 -9.38183e-07 -0.707105 0.707109" type="box" class="collision" />
      <body name="thumb_proximal_base" pos="0.0169601 0.0204504 0.0690999" quat="-0.707107 9.38192e-07 3.53553e-06 0.707106" childclass="inspire">
        <inertial pos="-0.0048064 0.0009382 -0.00757" quat="0.515015 0.680854 0.408023 0.323596" mass="0.0018869" diaginertia="8.66026e-08 6.8732e-08 4.94194e-08" />
        <joint name="thumb_proximal_yaw_joint" pos="0 0 0" axis="0 0 -1" range="0 1.308" actuatorfrcrange="-1 1" />
        <geom type="mesh" mesh="right_thumb_proximal_base" class="collision" />
        <geom class="visual" mesh="right_thumb_proximal_base_visual" />
        <body name="thumb_proximal" pos="-0.0088099 0.010892 -0.00925" quat="0.0996843 0.0996847 0.700046 0.700044">
          <inertial pos="0.021932 0.012785 -0.0080386" quat="-0.254474 0.660716 0.251893 0.659733" mass="0.0066075" diaginertia="2.78601e-06 2.43933e-06 8.64566e-07" />
          <joint name="thumb_proximal_pitch_joint" pos="0 0 0" axis="0 0 1" range="0 0.6" actuatorfrcrange="-1 1" />
          <geom type="mesh" mesh="right_thumb_proximal" class="collision" />
          <geom class="visual" mesh="right_thumb_proximal_visual" />
          <body name="thumb_intermediate" pos="0.04407 0.034553 -0.0008">
            <inertial pos="0.0095544 -0.0016282 -0.0071997" quat="0.636718 0.307389 -0.636802 0.307548" mass="0.0037847" diaginertia="4.6531e-07 4.48089e-07 2.45661e-07" />
            <joint name="thumb_intermediate_joint" pos="0 0 0" axis="0 0 1" range="0 0.8" actuatorfrcrange="-1 1" />
            <geom type="mesh" mesh="right_thumb_intermediate" class="collision" />
            <geom class="visual" mesh="right_thumb_intermediate_visual" />
            <body name="thumb_distal" pos="0.020248 0.010156 -0.0012">
              <inertial pos="0.0092888 0.0049529 -0.0060033" quat="-0.266294 0.655967 0.262806 0.655537" mass="0.0033441" diaginertia="2.0026e-07 1.95247e-07 8.1593e-08" />
              <joint name="thumb_distal_joint" pos="0 0 0" axis="0 0 1" range="0 0.4" actuatorfrcrange="-1 1" />
              <geom type="mesh" mesh="right_thumb_distal" class="collision" />
              <geom class="visual" mesh="right_thumb_distal_visual" />
            </body>
          </body>
        </body>
      </body>
      <body name="index_proximal" pos="-0.000285244 0.0322689 0.13653" quat="-9.21673e-07 -9.54413e-07 -0.719337 -0.694661" childclass="inspire">
        <inertial pos="0.0012259 0.011942 -0.0060001" quat="0.50867 0.49121 -0.508643 0.491172" mass="0.0042403" diaginertia="6.9398e-07 6.62871e-07 2.10909e-07" />
        <joint name="index_proximal_joint" pos="0 0 0" axis="0 0 1" range="0 1.47" actuatorfrcrange="-1 1" />
        <geom type="mesh" mesh="right_index_proximal" class="collision" />
        <geom class="visual" mesh="right_index_proximal_visual" />
        <body name="index_intermediate" pos="-0.0026138 0.032026 -0.001">
          <inertial pos="0.0019697 0.019589 -0.005" quat="0.466773 0.531152 -0.466773 0.531153" mass="0.0045683" diaginertia="7.8179e-07 7.72465e-07 8.47212e-08" />
          <joint name="index_intermediate_joint" pos="0 0 0" axis="0 0 1" range="-0.04545 1.56" actuatorfrcrange="-1 1" />
          <geom type="mesh" mesh="right_index_intermediate" class="collision" />
          <geom class="visual" mesh="right_index_intermediate_visual" />
        </body>
      </body>
      <body name="middle_proximal" pos="-0.000285296 0.0129509 0.1371" quat="-9.38186e-07 -9.38185e-07 -0.707106 -0.707107" childclass="inspire">
        <inertial pos="0.001297 0.011934 -0.0060001" quat="0.510131 0.489693 -0.510105 0.489653" mass="0.0042403" diaginertia="6.9397e-07 6.62865e-07 2.10915e-07" />
        <joint name="middle_proximal_joint" pos="0 0 0" axis="0 0 1" range="0 1.47" actuatorfrcrange="-1 1" />
        <geom type="mesh" mesh="right_index_proximal" class="collision" />
        <geom class="visual" mesh="right_index_proximal_visual" />
        <body name="middle_intermediate" pos="-0.0024229 0.032041 -0.001">
          <inertial pos="0.001921 0.020796 -0.005" quat="0.466148 0.531627 -0.466229 0.531705" mass="0.0050396" diaginertia="9.8384e-07 9.73279e-07 9.14014e-08" />
          <joint name="middle_intermediate_joint" pos="0 0 0" axis="0 0 1" range="-0.04545 1.56" actuatorfrcrange="-1 1" />
          <geom type="mesh" mesh="right_middle_intermediate" class="collision" />
          <geom class="visual" mesh="right_middle_intermediate_visual" />
        </body>
      </body>
      <body name="ring_proximal" pos="-0.000285347 -0.00628633 0.13691" quat="9.62435e-07 9.13293e-07 0.688345 0.725383" childclass="inspire">
        <inertial pos="0.001297 0.011934 -0.0060002" quat="0.510129 0.489691 -0.510107 0.489654" mass="0.0042403" diaginertia="6.9397e-07 6.62865e-07 2.10915e-07" />
        <joint name="ring_proximal_joint" pos="0 0 0" axis="0 0 1" range="0 1.47" actuatorfrcrange="-1 1" />
        <geom type="mesh" mesh="right_index_proximal" class="collision" />
        <geom class="visual" mesh="right_index_proximal_visual" />
        <body name="ring_intermediate" pos="-0.0024229 0.032041 -0.001">
          <inertial pos="0.0021753 0.019567 -0.005" quat="0.469554 0.528695 -0.469554 0.528695" mass="0.0045683" diaginertia="7.8177e-07 7.72448e-07 8.4722e-08" />
          <joint name="ring_intermediate_joint" pos="0 0 0" axis="0 0 1" range="-0.04545 1.56" actuatorfrcrange="-1 1" />
          <geom type="mesh" mesh="right_index_intermediate" class="collision" />
          <geom class="visual" mesh="right_index_intermediate_visual" />
        </body>
      </body>
      <body name="pinky_proximal" pos="-0.000285398 -0.0254871 0.13571" quat="9.85986e-07 8.87816e-07 0.669143 0.743134" childclass="inspire">
        <inertial pos="0.001297 0.011934 -0.0060001" quat="0.51013 0.489693 -0.510106 0.489653" mass="0.0042403" diaginertia="6.9397e-07 6.62865e-07 2.10915e-07" />
        <joint name="pinky_proximal_joint" pos="0 0 0" axis="0 0 1" range="0 1.47" actuatorfrcrange="-1 1" />
        <geom type="mesh" mesh="right_index_proximal" class="collision" />
        <geom class="visual" mesh="right_index_proximal_visual" />
        <body name="pinky_intermediate" pos="-0.0024229 0.032041 -0.001">
          <inertial pos="0.0024748 0.016203 -0.0050031" quat="0.47398 0.528862 -0.469291 0.524799" mass="0.0035996" diaginertia="4.4867e-07 4.43723e-07 6.56538e-08" />
          <joint name="pinky_intermediate_joint" pos="0 0 0" axis="0 0 1" range="-0.04545 1.56" actuatorfrcrange="-1 1" />
          <geom type="mesh" mesh="right_pinky_intermediate" class="collision" />
          <geom class="visual" mesh="right_pinky_intermediate_visual" />
        </body>
      </body>
    </body>
  </worldbody>

  <equality>
    <joint joint1="pinky_proximal_joint" joint2="pinky_intermediate_joint" polycoef="0 1 0 0 0"/>
    <joint joint1="ring_proximal_joint" joint2="ring_intermediate_joint" polycoef="0 1 0 0 0"/>
    <joint joint1="middle_proximal_joint" joint2="middle_intermediate_joint" polycoef="0 1 0 0 0"/>
    <joint joint1="index_proximal_joint" joint2="index_intermediate_joint" polycoef="0 1 0 0 0"/>
    <joint joint1="thumb_proximal_pitch_joint" joint2="thumb_intermediate_joint" polycoef="0 1 0 0 0"/>
    <joint joint1="thumb_distal_joint" joint2="thumb_intermediate_joint" polycoef="0 1 0 0 0"/>
  </equality>

  <actuator>
    <position name="pinky" joint="pinky_proximal_joint" ctrlrange="0 1.47" kp="10"/>
    <position name="ring" joint="ring_proximal_joint" ctrlrange="0 1.47" kp="10"/>
    <position name="middle" joint="middle_proximal_joint" ctrlrange="0 1.47" kp="10"/>
    <position name="index" joint="index_proximal_joint" ctrlrange="0 1.47" kp="10"/>
    <position name="thumb_proximal" joint="thumb_proximal_pitch_joint" ctrlrange="0 0.6" kp="10"/>
    <!-- <position name="thumb_yaw" joint="thumb_proximal_yaw_joint" ctrlrange="0 1.308" kp="10"/> -->
  </actuator>


</mujoco>
