<mujoco model="UR5e Inspire RH">
  <compiler angle="radian" meshdir="assets" autolimits="true"/>

  <!-- <option integrator="implicitfast"/> -->
   <option timestep="0.003"/>

  <default>
    <!-- UR5E defaults -->
    <default class="ur5e">
      <material specular="0.5" shininess="0.25"/>
      <joint axis="0 1 0" range="-6.28319 6.28319" armature="0.1" damping="2"/>
      <general gaintype="fixed" biastype="affine" ctrlrange="-6.2831 6.2831" gainprm="2000" biasprm="0 -2000 -400"
        forcerange="-150 150"/>
      <default class="size3">
        <default class="size3_limited">
          <joint range="-3.1415 3.1415"/>
          <general ctrlrange="-3.1415 3.1415"/>
        </default>
      </default>
      <default class="size1">
        <general gainprm="500" biasprm="0 -500 -100" forcerange="-28 28"/>
      </default>
      <default class="ur5e_visual">
        <geom type="mesh" contype="0" conaffinity="0" group="2"/>
      </default>
      <default class="ur5e_collision">
        <geom type="capsule" group="3"/>
        <default class="eef_collision">
          <geom type="cylinder"/>
        </default>

      </default>
      <site size="0.001" rgba="0.5 0.5 0.5 0.3" group="4"/>
    </default>

    <!-- Inspire hand defaults -->
    <default class="inspire">
      <position kp="100" dampratio="1.0" />
      <joint damping="0.1" armature="0.01" frictionloss="0.001" />
      <material specular="0.5" shininess="0.25" />
        <default class="visual">
          <geom type="mesh" contype="0" conaffinity="0" group="2" rgba="0.1 0.1 0.1 1"/>
        </default>
        <default class="collision">
          <geom type="mesh" group="3" condim="4" friction="1 0.005 0.001" solref="0.002 1" solimp="0.9 0.95 0.001" />
        </default>
     <site size="0.0035" type="sphere" rgba="1 0 0 1" group="3" />
    </default>
  </default>

  <asset>
    <!-- UR5E materials -->
    <material class="ur5e" name="black" rgba="0.033 0.033 0.033 1"/>
    <material class="ur5e" name="jointgray" rgba="0.278 0.278 0.278 1"/>
    <material class="ur5e" name="linkgray" rgba="0.82 0.82 0.82 1"/>
    <material class="ur5e" name="urblue" rgba="0.49 0.678 0.8 1"/>

    <!-- UR5E meshes -->
    <mesh file="ur5e/base_0.obj"/>
    <mesh file="ur5e/base_1.obj"/>
    <mesh file="ur5e/shoulder_0.obj"/>
    <mesh file="ur5e/shoulder_1.obj"/>
    <mesh file="ur5e/shoulder_2.obj"/>
    <mesh file="ur5e/upperarm_0.obj"/>
    <mesh file="ur5e/upperarm_1.obj"/>
    <mesh file="ur5e/upperarm_2.obj"/>
    <mesh file="ur5e/upperarm_3.obj"/>
    <mesh file="ur5e/forearm_0.obj"/>
    <mesh file="ur5e/forearm_1.obj"/>
    <mesh file="ur5e/forearm_2.obj"/>
    <mesh file="ur5e/forearm_3.obj"/>
    <mesh file="ur5e/wrist1_0.obj"/>
    <mesh file="ur5e/wrist1_1.obj"/>
    <mesh file="ur5e/wrist1_2.obj"/>
    <mesh file="ur5e/wrist2_0.obj"/>
    <mesh file="ur5e/wrist2_1.obj"/>
    <mesh file="ur5e/wrist2_2.obj"/>
    <mesh file="ur5e/wrist3.obj"/>

    <!-- UR5 Inspire Mount -->
    <mesh name="ur5_mount" content_type="model/stl" file="ur5_mount.stl"/>

    <!-- collision meshes -->
    <mesh name="right_thumb_proximal_base" file="collision/right_thumb_proximal_base.stl"/>
    <mesh name="right_thumb_proximal" file="collision/right_thumb_proximal.stl"/>
    <mesh name="right_thumb_intermediate" file="collision/right_thumb_intermediate.stl"/>
    <mesh name="right_thumb_distal" file="collision/right_thumb_distal.stl"/>
    <mesh name="right_index_proximal" file="collision/right_index_proximal.stl"/>
    <mesh name="right_index_intermediate" file="collision/right_index_intermediate.stl"/>
    <mesh name="right_middle_intermediate" file="collision/right_middle_intermediate.stl"/>
    <mesh name="right_pinky_intermediate" file="collision/right_pinky_intermediate.stl"/>

    <!-- visual meshes -->
    <!-- <mesh name="right_base_link_visual" file="visual/right_base_link_visual.stl"/> -->
    <mesh name="right_base_link_visual" file="visual/R_hand_base_link.STL"/>
    <mesh name="right_thumb_proximal_base_visual" file="visual/right_thumb_proximal_base_visual.stl" />
    <mesh name="right_thumb_proximal_visual" file="visual/right_thumb_proximal_visual.stl" />
    <mesh name="right_thumb_intermediate_visual" file="visual/right_thumb_intermediate_visual.stl" />
    <mesh name="right_thumb_distal_visual" file="visual/right_thumb_distal_visual.stl" />
    <mesh name="right_index_proximal_visual" file="visual/right_index_proximal_visual.stl" />
    <mesh name="right_index_intermediate_visual" file="visual/right_index_intermediate_visual.stl" />
    <mesh name="right_middle_intermediate_visual" file="visual/right_middle_intermediate_visual.stl" />
    <mesh name="right_pinky_intermediate_visual" file="visual/right_pinky_intermediate_visual.stl" />
  </asset>

  <worldbody>
    <light name="spotlight" mode="targetbodycom" target="wrist_2_link" pos="0 -1 2"/>
    <body name="base" quat="0 0 0 -1" childclass="ur5e">
      <inertial mass="4.0" pos="0 0 0" diaginertia="0.00443333156 0.00443333156 0.0072"/>
      <geom mesh="base_0" material="black" class="ur5e_visual"/>
      <geom mesh="base_1" material="jointgray" class="ur5e_visual"/>
      <body name="shoulder_link" gravcomp="1" pos="0 0 0.163">
        <inertial mass="3.7" pos="0 0 0" diaginertia="0.0102675 0.0102675 0.00666"/>
        <joint name="shoulder_pan_joint" class="size3" axis="0 0 1"/>
        <geom mesh="shoulder_0" material="urblue" class="ur5e_visual"/>
        <geom mesh="shoulder_1" material="black" class="ur5e_visual"/>
        <geom mesh="shoulder_2" material="jointgray" class="ur5e_visual"/>
        <geom class="ur5e_collision" size="0.06 0.06" pos="0 0 -0.04"/>
        <body name="upper_arm_link" gravcomp="1" pos="0 0.138 0" quat="1 0 1 0">
          <inertial mass="8.393" pos="0 0 0.2125" diaginertia="0.133886 0.133886 0.0151074"/>
          <joint name="shoulder_lift_joint" class="size3"/>
          <geom mesh="upperarm_0" material="linkgray" class="ur5e_visual"/>
          <geom mesh="upperarm_1" material="black" class="ur5e_visual"/>
          <geom mesh="upperarm_2" material="jointgray" class="ur5e_visual"/>
          <geom mesh="upperarm_3" material="urblue" class="ur5e_visual"/>
          <geom class="ur5e_collision" pos="0 -0.04 0" quat="1 1 0 0" size="0.06 0.06"/>
          <geom class="ur5e_collision" size="0.05 0.2" pos="0 0 0.2"/>
          <body name="forearm_link" gravcomp="1" pos="0 -0.131 0.425">
            <inertial mass="2.275" pos="0 0 0.196" diaginertia="0.0311796 0.0311796 0.004095"/>
            <joint name="elbow_joint" class="size3_limited"/>
            <geom mesh="forearm_0" material="urblue" class="ur5e_visual"/>
            <geom mesh="forearm_1" material="linkgray" class="ur5e_visual"/>
            <geom mesh="forearm_2" material="black" class="ur5e_visual"/>
            <geom mesh="forearm_3" material="jointgray" class="ur5e_visual"/>
            <geom class="ur5e_collision" pos="0 0.08 0" quat="1 1 0 0" size="0.055 0.06"/>
            <geom class="ur5e_collision" size="0.038 0.19" pos="0 0 0.2"/>
            <body name="wrist_1_link" gravcomp="1" pos="0 0 0.392" quat="1 0 1 0">
              <inertial mass="1.219" pos="0 0.127 0" diaginertia="0.0025599 0.0025599 0.0021942"/>
              <joint name="wrist_1_joint" class="size1"/>
              <geom mesh="wrist1_0" material="black" class="ur5e_visual"/>
              <geom mesh="wrist1_1" material="urblue" class="ur5e_visual"/>
              <geom mesh="wrist1_2" material="jointgray" class="ur5e_visual"/>
              <geom class="ur5e_collision" pos="0 0.05 0" quat="1 1 0 0" size="0.04 0.07"/>
              <body name="wrist_2_link" gravcomp="1" pos="0 0.127 0">
                <inertial mass="1.219" pos="0 0 0.1" diaginertia="0.0025599 0.0025599 0.0021942"/>
                <joint name="wrist_2_joint" axis="0 0 1" class="size1"/>
                <geom mesh="wrist2_0" material="black" class="ur5e_visual"/>
                <geom mesh="wrist2_1" material="urblue" class="ur5e_visual"/>
                <geom mesh="wrist2_2" material="jointgray" class="ur5e_visual"/>
                <geom class="ur5e_collision" size="0.04 0.06" pos="0 0 0.04"/>
                <geom class="ur5e_collision" pos="0 0.02 0.1" quat="1 1 0 0" size="0.04 0.04"/>
                <body name="wrist_3_link" gravcomp="1" pos="0 0 0.1">
                  <inertial mass="0.1889" pos="0 0.0771683 0" quat="1 0 0 1"
                    diaginertia="0.000132134 9.90863e-05 9.90863e-05"/>
                  <joint name="wrist_3_joint" class="size1"/>
                  <geom material="linkgray" mesh="wrist3" class="ur5e_visual"/>
                  <!-- Force/torque sensor site at wrist -->
                  <geom name="optoforce" size="0.035 0.0175" pos="0 0.1165 0" quat="0 0 -0.7071068 0.707168" density="0" type="cylinder" class="ur5e_visual" />
                  <geom name="optoforce_collision" size="0.035 0.0175" pos="0 0.1165 0" quat="0 0 0.7071068 0.707168" density="0" type="cylinder" class="ur5e_collision" />
                  <site name="wrist_ft" pos="0 0.12 0" size="0.01" rgba="1 1 0 0.5" group="3"/>
                  <geom type="mesh" name="ur5_mount" mesh="ur5_mount" pos="0 0.151 0" density="0" class="ur5e_visual"/>
                  <geom type="mesh" name="ur5_mount_collision" mesh="ur5_mount" pos="0 0.151 0" density="0" class="ur5e_collision"/>

                  <!-- Inspire hand attached to UR5E wrist -->
                  <!-- Attachment frame: UR5E Y-axis out, Magpie Z-axis out -->
                  <!-- quat rotates gripper so its Z aligns with UR5E +Y (-90° about X) -->
                  <body name="gripper_attachment" gravcomp="1" pos="0 0.156 0" quat="-0.707108 0.707108 0 0">
                    <include file="inspire_right_ur5.xml"/>
                  </body>

                </body>
              </body>
            </body>
          </body>
        </body>
      </body>
    </body>
  </worldbody>

  <!-- Equality constraints for magpie 4-bar loop closure -->
  <equality>
    <joint joint1="pinky_proximal_joint" joint2="pinky_intermediate_joint" polycoef="0 1 0 0 0"/>
    <joint joint1="ring_proximal_joint" joint2="ring_intermediate_joint" polycoef="0 1 0 0 0"/>
    <joint joint1="middle_proximal_joint" joint2="middle_intermediate_joint" polycoef="0 1 0 0 0"/>
    <joint joint1="index_proximal_joint" joint2="index_intermediate_joint" polycoef="0 1 0 0 0"/>
    <joint joint1="thumb_proximal_pitch_joint" joint2="thumb_intermediate_joint" polycoef="0 1 0 0 0"/>
    <joint joint1="thumb_distal_joint" joint2="thumb_intermediate_joint" polycoef="0 1 0 0 0"/>
  </equality>

  <actuator>
      <!-- UR5E arm actuators -->
    <!-- <general class="size3" name="shoulder_pan" joint="shoulder_pan_joint"/>
    <general class="size3" name="shoulder_lift" joint="shoulder_lift_joint"/>
    <general class="size3_limited" name="elbow" joint="elbow_joint"/>
    <general class="size1" name="wrist_1" joint="wrist_1_joint"/>
    <general class="size1" name="wrist_2" joint="wrist_2_joint"/>
    <general class="size1" name="wrist_3" joint="wrist_3_joint"/> -->

    <!-- End-effector 6D Cartesian Space Control -->
    <general site="eeff" refsite="world" ctrlrange="-1 1" ctrllimited="true" gainprm="10" gear="1 0 0 0 0 0"/>
    <general site="eeff" refsite="world" ctrlrange="-1 1" ctrllimited="true" gainprm="10" gear="0 1 0 0 0 0"/>
    <general site="eeff" refsite="world" ctrlrange="-1 1" ctrllimited="true" gainprm="10" gear="0 0 1 0 0 0"/>
    <general site="eeff" refsite="world" ctrlrange="-1 1" ctrllimited="true" gainprm="1" gear="0 0 0 1 0 0"/>
    <general site="eeff" refsite="world" ctrlrange="-1 1" ctrllimited="true" gainprm="1" gear="0 0 0 0 1 0"/>
    <general site="eeff" refsite="world" ctrlrange="-1 1" ctrllimited="true" gainprm="1" gear="0 0 0 0 0 1"/>

    <!-- Inspire hand actuators -->
    <position class="inspire" name="pinky" joint="pinky_proximal_joint" ctrlrange="0 1.57"/>
    <position class="inspire" name="ring" joint="ring_proximal_joint" ctrlrange="0 1.57"/>
    <position class="inspire" name="middle" joint="middle_proximal_joint" ctrlrange="0 1.57"/>
    <position class="inspire" name="index" joint="index_proximal_joint" ctrlrange="0 1.57"/>
    <position class="inspire" name="thumb_proximal" joint="thumb_proximal_pitch_joint" ctrlrange="0 0.6"/>
    <position class="inspire" name="thumb_yaw" joint="thumb_proximal_yaw_joint" ctrlrange="0 1.308"/>
  </actuator>

  <contact>
    <!-- Palm to finger proximal exclusions -->
    <exclude body1="base" body2="thumb_proximal_base"/>
    <exclude body1="base" body2="thumb_proximal"/>
    <exclude body1="gripper_attachment" body2="thumb_proximal"/>
    <exclude body1="base" body2="index_proximal"/>
    <exclude body1="base" body2="middle_proximal"/>
    <exclude body1="base" body2="ring_proximal"/>
    <exclude body1="base" body2="pinky_proximal"/>

    <!-- Thumb chain exclusions -->
    <exclude body1="thumb_proximal_base" body2="thumb_intermediate"/>
    <exclude body1="thumb_proximal" body2="thumb_intermediate"/>
    <exclude body1="thumb_intermediate" body2="thumb_distal"/>

    <!-- Finger chain exclusions -->
    <exclude body1="index_proximal" body2="index_intermediate"/>
    <exclude body1="middle_proximal" body2="middle_intermediate"/>
    <exclude body1="ring_proximal" body2="ring_intermediate"/>
    <exclude body1="pinky_proximal" body2="pinky_intermediate"/>

    <!-- Cross-finger exclusions at palm level -->
    <exclude body1="index_proximal" body2="middle_proximal"/>
    <exclude body1="middle_proximal" body2="ring_proximal"/>
    <exclude body1="ring_proximal" body2="pinky_proximal"/>

    <!-- Thumb-to-index exclusion -->
    <exclude body1="thumb_proximal_base" body2="index_proximal"/>
  </contact>

</mujoco>
